Workbook

Sheet RM
C1: Colum O to T should only Be Copied for Purchase Order | F1: 34
A2: Sl No. | B2: whether LifeBuoy? | C2: RAW MATERIAL NAME | D2: SAS Part Number | E2: OEM Part Number | F2: UNIT OF MEASURE | G2: SUPPLIER | H2: SAIFSEAS LIFE Final Assy (FG)
B3: A
A4: =IF(C4<>"",COUNTA($C$4:C4),"") -> 1 | B4: A | C4: Transmitter with Receiver Module 2.4G0.9k | D4: RAD-TRR-QX71W915 | E4: Robu-866205 | F4: Number | G4: Robu
A5: =IF(C5<>"",COUNTA($C$4:C5),"") -> 2 | B5: A | C5: Receiver Module R9MM (R9MM will come July25)/R9Mini | D5: RAD-TRR-R9MI1W915 | E5: Robu-866205 | F5: Number | G5: Robu
A6: =IF(C6<>"",COUNTA($C$4:C6),"") -> 3 | B6: A | C6: Free Wheel Diode SMD M7 | D6: SIC-DIO-M7-v100i1 | E6: Robu-597541 | F6: Number | G6: Robu
A7: =IF(C7<>"",COUNTA($C$4:C7),"") -> 4 | B7: A | C7: Schottky Diode SS310 100v1A | D7: SIC-DIO-SS310-v100i1 | E7: Robu-R193145 | F7: Number | G7: Robu
A8: =IF(C8<>"",COUNTA($C$4:C8),"") -> 5 | B8: A | C8: Voltage Regulator AMS1117 5.0v | D8: SIC-REG-AMS1117-5v | E8: Robu-162035 | F8: Number | G8: Robu
A9: =IF(C9<>"",COUNTA($C$4:C9),"") -> 6 | C9: GPS Module NEO-6M | D9: MOD-GNS-NEO6M | E9: Neo-6M | F9: Number | G9: Roland
A10: =IF(C10<>"",COUNTA($C$4:C10),"") -> 7 | B10: A | C10: GPS Module LC86L | D10: MOD-GNS-LC86L | E10: LC86L | F10: Number | G10: Roland
A11: =IF(C11<>"",COUNTA($C$4:C11),"") -> 8 | C11: GPS Module Here3+ | D11: MOD-GNS-LC86L | E11: Here3+ | F11: Number | G11: Gadgets Deal
A12: =IF(C12<>"",COUNTA($C$4:C12),"") -> 9 | C12: GPS Module BX992 Trimble | D12: MOD-GNS-BX992 | E12: BX992 | F12: Number | G12: Pan India Consultants
A13: =IF(C13<>"",COUNTA($C$4:C13),"") -> 10 | B13: A | C13: Bullet Connector Female 5.5mm | D13: CON-BUL-55F | E13: HV130 | F13: Number | G13: Hobbywing
A14: =IF(C14<>"",COUNTA($C$4:C14),"") -> 11 | B14: A | C14: Bullet Connector Male 4mm AMASS | D14: CON-BUL-4M | E14: Robu-239973 | F14: Number | G14: Robu
A15: =IF(C15<>"",COUNTA($C$4:C15),"") -> 12 | B15: A | C15: Bullet Connector Female 4mm AMASS | D15: CON-BUL-4F | E15: Robu-R150111 | F15: Number | G15: Robu
A16: =IF(C16<>"",COUNTA($C$4:C16),"") -> 13 | B16: A | C16: Bullet Connector Male 2mm AMASS | D16: CON-BUL-2M | E16: Robu-R150108 | F16: Number | G16: Robu
A17: =IF(C17<>"",COUNTA($C$4:C17),"") -> 14 | B17: A | C17: Bullet Connector Female 2mm AMASS | D17: CON-BUL-2F | E17: Robu-R150107 | F17: Number | G17: Robu
A18: =IF(C18<>"",COUNTA($C$4:C18),"") -> 15 | B18: A | C18: Bullet Connector Male 6mm XT-150 AMASS | D18: CON-BUL-6M | E18: Robu-239520 | F18: Number | G18: Robu
A19: =IF(C19<>"",COUNTA($C$4:C19),"") -> 16 | B19: A | C19: Bullet Connector Female 6mm XT-150 AMASS | D19: CON-BUL-6F | E19: Robu-239593 | F19: Number | G19: Robu
A20: =IF(C20<>"",COUNTA($C$4:C20),"") -> 17 | B20: A | C20: Bullet Connector Male 8mm AMASS | D20: CON-BUL-8M | E20: Robu-239739 | F20: Number | G20: Robu
A21: =IF(C21<>"",COUNTA($C$4:C21),"") -> 18 | B21: A | C21: Bullet Connector Female 8mm AMASS | D21: CON-BUL-8F | E21: Robu-239757 | F21: Number | G21: Robu
A22: =IF(C22<>"",COUNTA($C$4:C22),"") -> 19 | B22: A | C22: Cable - Ultra Flexible - Black 8AWG | D22: CAB-SIL-BLACK8AWG | E22: Robu-R151637 | F22: Meter | G22: Robu
A23: =IF(C23<>"",COUNTA($C$4:C23),"") -> 20 | B23: A | C23: Cable - Ultra Flexible - Red 8AWG | D23: CAB-SIL-RED8AWG | E23: Robu-R151638 | F23: Meter | G23: Robu
A24: =IF(C24<>"",COUNTA($C$4:C24),"") -> 21 | B24: A | C24: Cable - Ultra Flexible - Black 10AWG | D24: CAB-SIL-BLACK10AWG | F24: Meter | G24: Robu
A25: =IF(C25<>"",COUNTA($C$4:C25),"") -> 22 | B25: A | C25: Cable - Ultra Flexible - Red 10AWG | D25: CAB-SIL-RED10AWG | F25: Meter | G25: Robu
A26: =IF(C26<>"",COUNTA($C$4:C26),"") -> 23 | B26: A | C26: Cable - Ultra Flexible - Black 12AWG | D26: CAB-SIL-BLACK12AWG | E26: Robu-1824981 | F26: Meter | G26: Robu
A27: =IF(C27<>"",COUNTA($C$4:C27),"") -> 24 | B27: A | C27: Cable - Ultra Flexible - Red 12AWG | D27: CAB-SIL-RED12AWG | E27: Robu-1824982 | F27: Meter | G27: Robu
A28: =IF(C28<>"",COUNTA($C$4:C28),"") -> 25 | B28: A | C28: Cable - Ultra Flexible - Black 18 AWG | D28: CAB-SIL-BLACK18AWG | F28: Meter | G28: Robu
A29: =IF(C29<>"",COUNTA($C$4:C29),"") -> 26 | C29: Cable - Ultra Flexible - Red 18 AWG | D29: CAB-SIL-RED18AWG | F29: Meter | G29: Robu
C30: Cable - Ultra Flexible - Green 18 AWG | D30: CAB-SIL-GREEN18AWG
A31: =IF(C31<>"",COUNTA($C$4:C31),"") -> 28 | B31: A | C31: Cable - Ultra Flexible - Black 20 AWG | D31: CAB-SIL-BLACK20AWG | E31: Robu-1824989 | F31: Meter | G31: Robu
A32: =IF(C32<>"",COUNTA($C$4:C32),"") -> 29 | C32: Cable - Ultra Flexible - Green 20 AWG | D32: CAB-SIL-GREEN20AWG | F32: Meter | G32: Robu
A33: =IF(C33<>"",COUNTA($C$4:C33),"") -> 30 | B33: A | C33: Cable - Ultra Flexible Red 20 AWG | D33: CAB-SIL-RED20AWG | E33: Robu-1824992 | F33: Meter | G33: Robu
A34: =IF(C34<>"",COUNTA($C$4:C34),"") -> 31 | C34: Cable - Ultra Flexible Blue 20 AWG | D34: CAB-SIL-BLUE20AWG | E34: Robu-1824990 | F34: Meter | G34: Robu
A35: =IF(C35<>"",COUNTA($C$4:C35),"") -> 32 | C35: Water flow Sensor YFS401 | D35: SEN-WFL-YFS401v5 | E35: YFS401 | F35: Number | G35: Roland
A36: =IF(C36<>"",COUNTA($C$4:C36),"") -> 33 | C36: Water Pump 550 Diaphragm | D36: ACT-PMP-DIA550 | E36: 550 DIAPHRAGM | F36: Number | G36: Robu
A37: =IF(C37<>"",COUNTA($C$4:C37),"") -> 34 | C37: Battery Indicator - 1S Lipo | D37: IND-LIP-1S | F37: Number | G37: Robu
A38: =IF(C38<>"",COUNTA($C$4:C38),"") -> 35 | C38: Battery Indicator - 2S Lipo | D38: IND-LIP-2S | F38: Number | G38: Robu
A39: =IF(C39<>"",COUNTA($C$4:C39),"") -> 36 | C39: Lipo Indicator Casings | D39: IND-LIP-CASING | F39: Number | G39: Robu
A40: =IF(C40<>"",COUNTA($C$4:C40),"") -> 37 | C40: Buck Converter Module XL7015 50v | D40: MOD-BUK-XL7015v80i07 | E40: XL7015 | F40: Number | G40: Robu
...

Sheet 37-Self Rightening Assy
A1: Sl No. | B1: whether LifeBuoy? | C1: RAW MATERIAL NAME | D1: SAS Part Number | E1: OEM Part Number | F1: UNIT OF MEASURE | G1: SUPPLIER | H1: Self Rightening Assy
A2: 246 | B2: A | C2: SaifSeasLife Self Righting Structure | D2: FAB-ROT-SRSTRUCT-ORANGE | F2: Number | G2: Vinod Rai | H2: 1
A3: 247 | B3: A | C3: SaifSeasLife Self Righting Pillow | D3: FAB-ROT-SRPILLOW-ORANGE | F3: Number | G3: Vinod Rai | H3: 1
A4: 369 | B4: A | C4: Bolt Allen Head M6x150 SS 304 - SR Pillow & Structure | D4: FAS-BLT-ALN-6M150M-HX-304SS | F4: Number | G4: Dynamic Industrial Supplier | H4: 4
A5: 370 | B5: A | C5: Nut Nylock M6 SS 304 - SR Pillow & Structure | D5: FAS-NUT-6M-NYL-304SS | F5: Number | G5: Dynamic Industrial Supplier | H5: 4
A6: 438 | B6: A | C6: Sealant Teroson MS930 | D6: SLN-SMP-MS930-400ML | F6: ml | G6: Innovine Tech Marketing PVt. Ltd. | H6: 10
A7: 450 | B7: A | C7: RR Tape | D7: MAC-ADH-TAPE-RR | F7: Meter | G7: Local Market | H7: 5
A8: 514 | B8: A | C8: BPSPLB - Self Righting Pillow Caps 3D Printed | D8: FAB-3DP-PILCAP-SSLIFE | F8: Number | G8: In-house | H8: 4

Sheet 36-ESC Assy
A1: Sl No. | B1: whether LifeBuoy? | C1: RAW MATERIAL NAME | D1: SAS Part Number | E1: OEM Part Number | F1: UNIT OF MEASURE | G1: SUPPLIER | H1: ESC Assy
A2: 18 | B2: A | C2: Bullet Connector Female 8mm AMASS | D2: CON-BUL-8F | E2: Robu-239757 | F2: Number | G2: Robu | H2: 3
A3: 539 | B3: A | C3: Electronic Speed Controller - HV130 ESC | D3: MOD-ESC-HV130 | E3: HV 130 | F3: Number | G3: Hobbywing | H3: 1

Sheet 35-Charger Panel Assy
A1: Sl No. | B1: whether LifeBuoy? | C1: RAW MATERIAL NAME | D1: SAS Part Number | E1: OEM Part Number | F1: UNIT OF MEASURE | G1: SUPPLIER | H1: Charger Panel Assy
A2: 218 | B2: A | C2: 12 Core Wire 14/38 | D2: CAB-MCO-12C14/38LENChetan | F2: Meter | G2: Cable Fort | H2: 0.2
A3: 308 | B3: A | C3: Washer Plain M3x10x1 SS 304 - Charger Panel | D3: FAS-WAS-PWS-3M10M1M-304SS | F3: Number | G3: Dynamic Industrial Supplier | H3: 4
A4: 309 | B4: A | C4: M3x10 CSK | F4: Number | G4: Dynamic Industrial Supplier | H4: 16
A5: 353 | B5: A | C5: Nut Square M3 SS 304 - Charger panel | D5: FAS-NUT-3M-SQR-304SS | F5: Number | G5: Dynamic Industrial Supplier | H5: 4
A6: 354 | B6: A | C6: M3 Hex Nuts - Charger | D6: FAS-NUT-3M-HEX-SS304 | F6: Number | G6: Dynamic Industrial Supplier | H6: 12
A7: 438 | B7: A | C7: Sealant Teroson MS930 | D7: SLN-SMP-MS930-400ML | F7: ml | G7: Innovine Tech Marketing PVt. Ltd. | H7: 5
A8: 529 | B8: A | C8: Charger - Panel Pillar Spacer 3D Print | D8: FAB-3DP-X16-EXT-PILLER | F8: Number | G8: In House | H8: 2

Sheet 34-Charger power module Assy
A1: Sl No. | B1: whether LifeBuoy? | C1: RAW MATERIAL NAME | D1: SAS Part Number | E1: OEM Part Number | F1: UNIT OF MEASURE | G1: SUPPLIER | H1: Charger power module Assy
B2: A | H2: 34
A3: 40 | B3: A | C3: Buck Converter Module XL4015 5A | D3: MOD-BUK-XL4015v40i5 | E3: Robu-1510171 | F3: Number | G3: Robu | H3: 1
A4: 50 | B4: A | C4: Converter AC/DC - 24v | D4: MOD-HLK-W20v24i08 | E4: HLK-20M24 | F4: Number | G4: Rajguru | H4: 1
A5: 60 | B5: A | C5: PWB for PC Inside Charger with XL4015 buck | D5: PCB-X16-XL4015-CHARGER | F5: Number | G5: JLC | H5: 1
A6: 221 | B6: A | C6: 6 Core Wire 14/38 | D6: CAB-MCO-6C14/38LENChetan | F6: Meter | G6: Cable Fort | H6: 0.2

Sheet 33-Charger PM Assy
A1: Sl No. | B1: whether LifeBuoy? | C1: RAW MATERIAL NAME | D1: SAS Part Number | E1: OEM Part Number | F1: UNIT OF MEASURE | G1: SUPPLIER | H1: Charger PM Assy
B2: A | H2: 33
A3: 28 | B3: A | C3: Cable - Ultra Flexible - Black 20 AWG | D3: CAB-SIL-BLACK20AWG | E3: Robu-1824989 | F3: Meter | G3: Robu | H3: 0.3
A4: 30 | B4: A | C4: Cable - Ultra Flexible Red 20 AWG | D4: CAB-SIL-RED20AWG | E4: Robu-1824992 | F4: Meter | G4: Robu | H4: 0.3
A5: 43 | B5: A | C5: Connector - XT90 Female AMASS | D5: CON-BTC-XT90F | E5: Robu-24729 | F5: Number | G5: Robu | H5: 1
A6: 81 | B6: A | C6: Lead Wire 22AWG | D6: SOL-WIR-6040-ROHS-22AWG | F6: grm | G6: Roland | H6: 5
A7: 200 | B7: A | C7: Cable Balancing Microfit | D7: CAB-BAL-MFIT20CM20WGISDT | F7: Number | G7: Shenzen ISD Technology | H7: 1
A8: 283 | B8: A | C8: Connector Circular Socket Clip Lock PM Male LP24 24 Pin | D8: CON-CRS-LP24PF-PM-M24PL67 | E8: LP24-C24SX-03-401 | F8: Number | G8: Evelta | H8: 1
A9: 428 | B9: A | C9: HeatShrink Tube 2mm | D9: SLN-STB-2.0M-4X-BK | F9: Meter | G9: Robu | H9: 20

Sheet 32-IP Remote Charging Cable Ass
A1: Sl No. | B1: whether LifeBuoy? | C1: RAW MATERIAL NAME | D1: SAS Part Number | E1: OEM Part Number | F1: UNIT OF MEASURE | G1: SUPPLIER | H1: IP Remote Charging Cable Assy
A2: 78 | C2: Cable USB Data & Charging Cable 1m | D2: CAB-USB-1i5M24AWG | F2: Number | G2: Roland | H2: 1
A3: 275 | B3: A | C3: Connector Circular Push Pull CM Male SA12 9pin | D3: CON-CRC-SA12PF-CM-M9AL67-ST | E3: SA1210/P9IB | F3: Number | G3: Weipu | H3: 1
A4: 427 | B4: A | C4: HeatShrink Tube 1.5mm/1.6mm | D4: SLN-STB-1.6M-4X-BK | F4: cm | G4: Suzhou Volsun Electronics Technology | H4: 4

Sheet 31-IP Remote Charging PM
A1: Sl No. | B1: whether LifeBuoy? | C1: RAW MATERIAL NAME | D1: SAS Part Number | E1: OEM Part Number | F1: UNIT OF MEASURE | G1: SUPPLIER | H1: IP Remote Charging PM
B2: A | H2: 31
A3: 276 | B3: A | C3: Connector Circular Push Pull PM Female SA12 9pin | D3: CON-CRC-SA12PF-PM-F9AL67-ST | E3: SA1212/S9B | F3: Number | G3: Weipu | H3: 1
A4: 427 | B4: A | C4: HeatShrink Tube 1.5mm/1.6mm | D4: SLN-STB-1.6M-4X-BK | F4: cm | G4: Suzhou Volsun Electronics Technology | H4: 10

Sheet 30-Charging Cable Assy
A1: Sl No. | B1: whether LifeBuoy? | C1: RAW MATERIAL NAME | D1: SAS Part Number | E1: OEM Part Number | F1: UNIT OF MEASURE | G1: SUPPLIER | H1: Charging Cable Assy
A2: 216 | B2: A | C2: 20 Core Wire 14/38 | D2: CAB-MCO-20C14/38LENChetan | F2: Meter | G2: Cable Fort | H2: 1.25
A3: 273 | B3: A | C3: Connector Circular CM Metal Male WY-28 | D3: CON-CRC-WY28BY-CM-M26AL67-RA | E3: WY28J26TE1 | F3: Number | G3: Weipu | H3: 1
A4: 282 | B4: A | C4: Connector Circular Plug Clip Lock CM Female LP24 24-Pin | D4: CON-CRS-LP24PF-CM-F24PL67-ST | E4: LP24-J24PE-01-001 | F4: Number | G4: Evelta | H4: 1
A5: 427 | B5: A | C5: HeatShrink Tube 1.5mm/1.6mm | D5: SLN-STB-1.6M-4X-BK | F5: cm | G5: Suzhou Volsun Electronics Technology | H5: 20

Sheet 28-Jet body Assy STBD
A1: Sl No. | B1: whether LifeBuoy? | C1: RAW MATERIAL NAME | D1: SAS Part Number | E1: OEM Part Number | F1: UNIT OF MEASURE | G1: SUPPLIER | H1: Jet body Assy STBD
A2: 359 | B2: A | C2: Grub Screws M5x5 SS304 | D2: FAS-GRB-4M5M-HX-304SS | F2: Number | G2: Dynamic Industrial Supplier | H2: 2
A3: 457 | C3: Greasing Nipple M5 | F3: Number | G3: Taha HAjee | H3: 2
A4: 459 | B4: A | C4: I52 Jet Nozzles CW used on STBD side NEW | G4: Bagnan | H4: 1
A5: 461 | B5: A | C5: I52 Jet Stator CW (STBD) NEW | G5: Bagnan | H5: 1
A6: 463 | B6: A | C6: I52 Jet Impeller CW (STBD) NEW | G6: Bagnan | H6: 1
A7: 465 | B7: A | C7: I52 Impeller Shaft | G7: Bagnan | H7: 1
A8: 466 | B8: A | C8: I52 Shaft with Teflon Bush 7mm | G8: Bagnan | H8: 1
A9: 467 | B9: A | C9: Self Aligning Bearing IJK-108 | D9: MAC-BEARING-IJK108 | G9: Local Market Kolkata | H9: 2
A10: 468 | B10: A | C10: Jet S52 - Aluminium Spacer No. 1 (0.9mm) | D10: FAB-MCN-S52-SPACER09 | G10: Bagnan | H10: 1
A11: 469 | B11: A | C11: Jet S52 - Aluminium Greasing Spacer | D11: FAB-MCN-S52-SPACERMID | G11: Bagnan | H11: 1
A12: 470 | B12: A | C12: Jet S52 - Aluminium Spacer No. 2 (5.5mm) | D12: FAB-MCN-S52-SPACER5.5 | G12: Bagnan | H12: 1
A13: 471 | B13: A | C13: Oil Seal Jet 10-18-6 | D13: MAC-OILSEAS-10-18-6 | G13: Local Market Kolkata | H13: 1
A14: 472 | B14: A | C14: Oil Seal Stator 7-16-5 | D14: MAC-OILSEAS-7-16-5 | G14: Local Market Kolkata | H14: 1
A15: 476 | B15: A | C15: Circlip Jet 22mm | D15: MAC-CIRCLIP-22MM-SS | G15: Local Market Kolkata | H15: 1
A16: 656 | B16: A | C16: QC Sticker | F16: Number | G16: Local Market | H16: 1

Sheet 27-Jet body Assy
A1: Sl No. | B1: whether LifeBuoy? | C1: RAW MATERIAL NAME | D1: SAS Part Number | E1: OEM Part Number | F1: UNIT OF MEASURE | G1: SUPPLIER | H1: Jet body Assy PORT
A2: 359 | B2: A | C2: Grub Screws M5x5 SS304 | D2: FAS-GRB-4M5M-HX-304SS | F2: Number | G2: Dynamic Industrial Supplier | H2: 2
A3: 457 | C3: Greasing Nipple M5 | F3: Number | G3: Taha HAjee | H3: 2
A4: 460 | B4: A | C4: I52 Jet Nozzles CCW used on PORT side OLD | E4: f | G4: Bagnan | H4: 1
A5: 462 | B5: A | C5: I52 Jet Stator CCW (PORT) OLD | G5: Bagnan | H5: 1
A6: 464 | B6: A | C6: I52 Jet Impeller CCW (PORT) OLD | G6: Bagnan | H6: 1
A7: 465 | B7: A | C7: I52 Impeller Shaft | G7: Bagnan | H7: 1
A8: 466 | B8: A | C8: I52 Shaft with Teflon Bush 7mm | G8: Bagnan | H8: 1
A9: 467 | B9: A | C9: Self Aligning Bearing IJK-108 | D9: MAC-BEARING-IJK108 | G9: Local Market Kolkata | H9: 2
A10: 468 | B10: A | C10: Jet S52 - Aluminium Spacer No. 1 (0.9mm) | D10: FAB-MCN-S52-SPACER09 | G10: Bagnan | H10: 1
A11: 469 | B11: A | C11: Jet S52 - Aluminium Greasing Spacer | D11: FAB-MCN-S52-SPACERMID | G11: Bagnan | H11: 1
A12: 470 | B12: A | C12: Jet S52 - Aluminium Spacer No. 2 (5.5mm) | D12: FAB-MCN-S52-SPACER5.5 | G12: Bagnan | H12: 1
A13: 471 | B13: A | C13: Oil Seal Jet 10-18-6 | D13: MAC-OILSEAS-10-18-6 | G13: Local Market Kolkata | H13: 1
A14: 472 | B14: A | C14: Oil Seal Stator 7-16-5 | D14: MAC-OILSEAS-7-16-5 | G14: Local Market Kolkata | H14: 1
A15: 476 | B15: A | C15: Circlip Jet 22mm | D15: MAC-CIRCLIP-22MM-SS | G15: Local Market Kolkata | H15: 1
A16: 656 | B16: A | C16: QC Sticker | F16: Number | G16: Local Market | H16: 1

Sheet 26-Motor Mount Assy (V1.1 & 569
A1: Sl No. | B1: whether LifeBuoy? | C1: RAW MATERIAL NAME | D1: SAS Part Number | E1: OEM Part Number | F1: UNIT OF MEASURE | G1: SUPPLIER | H1: Motor Mount Assy (V1.1 & 5692)
A2: 321 | B2: A | C2: Bolt Allen Head M4x12 SS 304 - Motor Mount | D2: FAS-BLT-ALN-4M12M-HX-304SS | F2: Number | G2: Dynamic Industrial Supplier | H2: 6
A3: 437 | B3: A | C3: Heat Sink Paste | D3: HET-PAS-SIL-1W | F3: Grm | G3: Svtherm Technologies | H3: 5
A4: 492 | B4: A | C4: 5692-I52 Motor Mount Heatblock TOP Ver1.1 Integrated Jet | D4: FAB-MCN-5692HE-I52-TMOUNT-V1.1 | F4: Number | G4: D. B. Smelting | H4: 1
A5: 494 | B5: A | C5: 5692-I52 Motor mount heatblock BOTTOM Ver1.1 Integrated Jet | D5: FAB-MCN-5692HE-I52-BMOUNT-V1.1 | F5: Number | G5: D. B. Smelting | H5: 1
A6: 537 | B6: A | C6: Actuator - Motor 5692 495 KV | D6: ACT-MTR-5692KW3i5KV485LEO | E6: 5962 495KV | F6: Number | G6: Leopard | H6: 1

Sheet 25-Kangaroo box STBD Assy
A1: Sl No. | B1: whether LifeBuoy? | C1: RAW MATERIAL NAME | D1: SAS Part Number | E1: OEM Part Number | F1: UNIT OF MEASURE | G1: SUPPLIER | H1: Kangaroo box STBD Assy
A2: 691 | B2: A | C2: Signal Cable Assy | E2: 6 | F2: Number | G2: In House | H2: 1
A3: 707 | B3: A | C3: Kangaroo Power Wire STBD Assy | E3: 22 | F3: Number | G3: In House | H3: 1
A4: 708 | B4: A | C4: Kangaroo Box Preprocessing Assy | E4: 23 | F4: Number | G4: In House | H4: 1

Sheet 24-Kangaroo box PORT Assy
A1: Sl No. | B1: whether LifeBuoy? | C1: RAW MATERIAL NAME | D1: SAS Part Number | E1: OEM Part Number | F1: UNIT OF MEASURE | G1: SUPPLIER | H1: Kangaroo box PORT Assy
A2: 691 | B2: A | C2: Signal Cable Assy | E2: 6 | F2: Number | G2: In House | H2: 1
A3: 706 | B3: A | C3: Kangaroo Power Wire PORT Assy | E3: 21 | F3: Number | G3: In House | H3: 1
A4: 708 | B4: A | C4: Kangaroo Box Preprocessing Assy | E4: 23 | F4: Number | G4: In House | H4: 1

Sheet 23-Kangaroo Box Preprocessing A
A1: Sl No. | B1: whether LifeBuoy? | C1: RAW MATERIAL NAME | D1: SAS Part Number | E1: OEM Part Number | F1: UNIT OF MEASURE | G1: SUPPLIER | H1: Kangaroo Box Preprocessing Assy
A2: 254 | B2: A | C2: Kangaroo Box | D2: FAB-IJM-Kangaroo-Box | F2: Number | G2: Vinod Rai | H2: 1
A3: 401 | B3: A | C3: Cable gland PG-7 | D3: MAC-GLA-PG7-PL | F3: Number | G3: NDP | H3: 2
A4: 403 | C4: PG-9 Cable Gland Metal | H4: 1

Sheet 22-Kangaroo Power Wire STBD Ass
A1: Sl No. | B1: whether LifeBuoy? | C1: RAW MATERIAL NAME | D1: SAS Part Number | E1: OEM Part Number | F1: UNIT OF MEASURE | G1: SUPPLIER | H1: Kangaroo Power Wire STBD Assy
A2: 15 | B2: A | C2: Bullet Connector Male 6mm XT-150 AMASS | D2: CON-BUL-6M | E2: Robu-239520 | F2: Number | G2: Robu | H2: 1
A3: 16 | B3: A | C3: Bullet Connector Female 6mm XT-150 AMASS | D3: CON-BUL-6F | E3: Robu-239593 | F3: Number | G3: Robu | H3: 2
A4: 17 | B4: A | C4: Bullet Connector Male 8mm AMASS | D4: CON-BUL-8M | E4: Robu-239739 | F4: Number | G4: Robu | H4: 1
A5: 21 | B5: A | C5: Cable - Ultra Flexible - Black 10AWG | D5: CAB-SIL-BLACK10AWG | F5: Meter | G5: Robu | H5: 0.65
A6: 22 | B6: A | C6: Cable - Ultra Flexible - Red 10AWG | D6: CAB-SIL-RED10AWG | F6: Meter | G6: Robu | H6: 0.7
A7: 398 | B7: A | C7: Soldering Lead Wire 6040 16AWG | D7: SOL-WIR-6040-ROHS-16AWG | F7: Grm | G7: ARB Accessories | H7: 5
A8: 420 | B8: A | C8: Heatshrink Tube 6.4:1.6 Adhesive Lined Black | D8: SLN-STB-6.4M-4X-BK-ADH | F8: cm | G8: Suzhou Volsun Electronics Technology | H8: 7
A9: 421 | B9: A | C9: Heatshrink Tube 9.5mm Adhesive Lined Black | D9: SLN-STB-9.5M-3X-BK-ADH | F9: cm | G9: Suzhou Volsun Electronics Technology | H9: 3.5
A10: 426 | B10: A | C10: HeatShrink Tube 4.8/1.2 Adhesive Lined Black | D10: SLN-STB-4.8M-4X-BK-ADH | F10: cm | G10: Suzhou Volsun Electronics Technology | H10: 3.5

Sheet 21-Kangaroo Power Wire PORT Ass
A1: Sl No. | B1: whether LifeBuoy? | C1: RAW MATERIAL NAME | D1: SAS Part Number | E1: OEM Part Number | F1: UNIT OF MEASURE | G1: SUPPLIER | H1: Kangaroo Power Wire PORT Assy
A2: 12 | B2: A | C2: Bullet Connector Female 4mm AMASS | D2: CON-BUL-4F | E2: Robu-R150111 | F2: Number | G2: Robu | H2: 2
A3: 14 | B3: A | C3: Bullet Connector Female 2mm AMASS | D3: CON-BUL-2F | E3: Robu-R150107 | F3: Number | G3: Robu | H3: 1
A4: 15 | B4: A | C4: Bullet Connector Male 6mm XT-150 AMASS | D4: CON-BUL-6M | E4: Robu-239520 | F4: Number | G4: Robu | H4: 1
A5: 16 | B5: A | C5: Bullet Connector Female 6mm XT-150 AMASS | D5: CON-BUL-6F | E5: Robu-239593 | F5: Number | G5: Robu | H5: 1
A6: 18 | B6: A | C6: Bullet Connector Female 8mm AMASS | D6: CON-BUL-8F | E6: Robu-239757 | F6: Number | G6: Robu | H6: 1
A7: 21 | B7: A | C7: Cable - Ultra Flexible - Black 10AWG | D7: CAB-SIL-BLACK10AWG | F7: Meter | G7: Robu | H7: 0.63
A8: 22 | B8: A | C8: Cable - Ultra Flexible - Red 10AWG | D8: CAB-SIL-RED10AWG | F8: Meter | G8: Robu | H8: 0.65
A9: 23 | B9: A | C9: Cable - Ultra Flexible - Black 12AWG | D9: CAB-SIL-BLACK12AWG | E9: Robu-1824981 | F9: Meter | G9: Robu | H9: 0.05
A10: 25 | B10: A | C10: Cable - Ultra Flexible - Black 18 AWG | D10: CAB-SIL-BLACK18AWG | F10: Meter | G10: Robu | H10: 0.25
A11: 398 | B11: A | C11: Soldering Lead Wire 6040 16AWG | D11: SOL-WIR-6040-ROHS-16AWG | F11: Grm | G11: ARB Accessories | H11: 10
A12: 420 | B12: A | C12: Heatshrink Tube 6.4:1.6 Adhesive Lined Black | D12: SLN-STB-6.4M-4X-BK-ADH | F12: cm | G12: Suzhou Volsun Electronics Technology | H12: 8
A13: 421 | B13: A | C13: Heatshrink Tube 9.5mm Adhesive Lined Black | D13: SLN-STB-9.5M-3X-BK-ADH | F13: cm | G13: Suzhou Volsun Electronics Technology | H13: 7
A14: 425 | B14: A | C14: HeatShrink Tube 12:3 Adhesive Lined Black | D14: SLN-STB-12M-4X-BK-ADH | F14: cm | G14: Suzhou Volsun Electronics Technology | H14: 3.5

Sheet 20-Flashing Light Assy STBD
A1: Sl No. | B1: whether LifeBuoy? | C1: RAW MATERIAL NAME | D1: SAS Part Number | E1: OEM Part Number | F1: UNIT OF MEASURE | G1: SUPPLIER | H1: Flashing Light Assy STBD
A2: 13 | B2: A | C2: Bullet Connector Male 2mm AMASS | D2: CON-BUL-2M | E2: Robu-R150108 | F2: Number | G2: Robu | H2: 1
A3: 55 | B3: A | C3: PCB of STBD flash light | D3: PCB-STBD-FLASH | F3: Number | G3: JLC | H3: 1
A4: 297 | B4: A | C4: LED SMD Green 2835 1W | D4: IND-SMD-W1LEG-GR | E4: 1w 350mA Emitter Green | F4: Number | G4: Premier Electronics | H4: 4
B5: A | C5: Bolt Button Head M3x8 SS 304 Flashing Lights | D5: FAS-BLT-BUT-3M8M-HX-304SS | F5: Number | G5: Dynamic Industrial Supplier | H5: 6
A6: 398 | B6: A | C6: Soldering Lead Wire 6040 16AWG | D6: SOL-WIR-6040-ROHS-16AWG | F6: Grm | G6: ARB Accessories | H6: 1
A7: 415 | B7: A | C7: Flashing Light - Upper Glass Shell | D7: FAB-IJM-FLSH-GLASS | F7: Number | G7: Janki Die | H7: 1
A8: 416 | B8: A | C8: Flashing Light - Bottom Plate | D8: FAB-IJM-FLSH-PLATE | F8: Number | G8: Janki Die | H8: 1
A9: 437 | B9: A | C9: Heat Sink Paste | D9: HET-PAS-SIL-1W | F9: Grm | G9: Svtherm Technologies | H9: 2
A10: 438 | B10: A | C10: Sealant Teroson MS930 | D10: SLN-SMP-MS930-400ML | F10: ml | G10: Innovine Tech Marketing PVt. Ltd. | H10: 3

Sheet 19-Flashing Light Assy PORT
A1: Sl No. | B1: whether LifeBuoy? | C1: RAW MATERIAL NAME | D1: SAS Part Number | E1: OEM Part Number | F1: UNIT OF MEASURE | G1: SUPPLIER | H1: Flashing Light Assy PORT
A2: 13 | B2: A | C2: Bullet Connector Male 2mm AMASS | D2: CON-BUL-2M | E2: Robu-R150108 | F2: Number | G2: Robu | H2: 1
A3: 56 | B3: A | C3: PCB of PORT flash light | D3: PCB-PORT-FLASH | F3: Number | G3: JLC | H3: 1
A4: 296 | B4: A | C4: LED SMD Red 2835 1W | D4: IND-SMD-W1LEG-RD | E4: 1w 350mA Emitter Red | F4: Number | G4: Premier Electronics | H4: 6
B5: A | C5: Bolt Button Head M3x8 SS 304 Flashing Lights | D5: FAS-BLT-BUT-3M8M-HX-304SS | F5: Number | G5: Dynamic Industrial Supplier | H5: 6
A6: 398 | B6: A | C6: Soldering Lead Wire 6040 16AWG | D6: SOL-WIR-6040-ROHS-16AWG | F6: Grm | G6: ARB Accessories | H6: 1
A7: 415 | B7: A | C7: Flashing Light - Upper Glass Shell | D7: FAB-IJM-FLSH-GLASS | F7: Number | G7: Janki Die | H7: 1
A8: 416 | B8: A | C8: Flashing Light - Bottom Plate | D8: FAB-IJM-FLSH-PLATE | F8: Number | G8: Janki Die | H8: 1
A9: 437 | B9: A | C9: Heat Sink Paste | D9: HET-PAS-SIL-1W | F9: Grm | G9: Svtherm Technologies | H9: 2
A10: 438 | B10: A | C10: Sealant Teroson MS930 | D10: SLN-SMP-MS930-400ML | F10: ml | G10: Innovine Tech Marketing PVt. Ltd. | H10: 3

Sheet 18-Bottom block Assy
A1: Sl No. | B1: whether LifeBuoy? | C1: RAW MATERIAL NAME | D1: SAS Part Number | E1: OEM Part Number | F1: UNIT OF MEASURE | G1: SUPPLIER | H1: Bottom block Assy
A2: 302 | B2: A | C2: Bolt M3x8 CSK Phillips - Inlet Block Mesh | D2: FAS-BLT-CSK-3M8M-PH-304SS | F2: Number | G2: Dynamic Industrial Supplier | H2: 7
A3: 348 | B3: A | C3: Plain Washer M4x12x1 SS 304 - Jet with hull, Inlet block | D3: FAS-WAS-PWS-4M12M1M-304SS | F3: Number | G3: Dynamic Industrial Supplier | H3: 6
A4: 548 | B4: A | C4: BPSPLB - Bottom Mesh 120mm x 100mm, 5"x4" | D4: MAC-MESH-5x4M5 | F4: Meter | G4: Jain Wire Netting | H4: 1

Sheet 17-Charging PM Assy
A1: Sl No. | B1: whether LifeBuoy? | C1: RAW MATERIAL NAME | D1: SAS Part Number | E1: OEM Part Number | F1: UNIT OF MEASURE | G1: SUPPLIER | H1: Charging PM Assy
A2: 13 | B2: A | C2: Bullet Connector Male 2mm AMASS | D2: CON-BUL-2M | E2: Robu-R150108 | F2: Number | G2: Robu | H2: 2
A3: 28 | B3: A | C3: Cable - Ultra Flexible - Black 20 AWG | D3: CAB-SIL-BLACK20AWG | E3: Robu-1824989 | F3: Meter | G3: Robu | H3: 0.12
A4: 30 | B4: A | C4: Cable - Ultra Flexible Red 20 AWG | D4: CAB-SIL-RED20AWG | E4: Robu-1824992 | F4: Meter | G4: Robu | H4: 0.1
A5: 81 | B5: A | C5: Lead Wire 22AWG | D5: SOL-WIR-6040-ROHS-22AWG | F5: grm | G5: Roland | H5: 3
A6: 161 | B6: A | C6: Connector Housing 13 pin JST-XH | D6: CON-JXH-HOS-F13 | F6: Number | G6: Canner Connectors | H6: 1
A7: 193 | B7: A | C7: Cable Crimped JST One Side White with Black Strip 10cm | D7: CAB-CRI-2515WHITEBLACK10CM14/38 | F7: Number | G7: Canner Connectors | H7: 10
A8: 195 | B8: A | C8: Cable Crimped JST One Side Red 10cm | D8: CAB-CRI-2515RED10CM14/38 | F8: Number | G8: Canner Connectors | H8: 1
A9: 198 | B9: A | C9: Cable Crimped JST One Side Cyan 10cm | D9: CAB-CRI-2515CYAN10CM14/38 | F9: Number | G9: Canner Connectors | H9: 1
A10: 423 | B10: A | C10: HeatShrink Tube 3.2 mm Adhesive Lined Black | D10: SLN-STB-3M-3X-BK-ADH | F10: cm | G10: Suzhou Volsun Electronics Technology | H10: 5
A11: 427 | B11: A | C11: HeatShrink Tube 1.5mm/1.6mm | D11: SLN-STB-1.6M-4X-BK | F11: cm | G11: Suzhou Volsun Electronics Technology | H11: 12
A12: 428 | B12: A | C12: HeatShrink Tube 2mm | D12: SLN-STB-2.0M-4X-BK | F12: Meter | G12: Robu | H12: 6

Sheet 16-Signal PM Assy
A1: Sl No. | B1: whether LifeBuoy? | C1: RAW MATERIAL NAME | D1: SAS Part Number | E1: OEM Part Number | F1: UNIT OF MEASURE | G1: SUPPLIER | H1: Signal PM Assy
A2: 81 | B2: A | C2: Lead Wire 22AWG | D2: SOL-WIR-6040-ROHS-22AWG | F2: grm | G2: Roland | H2: 5
A3: 162 | B3: A | C3: Connector Housing 15 pin JST-XH | D3: CON-JXH-HOS-F15 | F3: Number | G3: Canner Connectors | H3: 1
A4: 182 | B4: A | C4: Cable Crimped JST One Side Black 10cm | D4: CAB-CRI-2515BLACK10CM14/38 | F4: Number | G4: Canner Connectors | H4: 1
A5: 183 | B5: A | C5: Cable Crimped JST One Side Green 10cm | D5: CAB-CRI-2515GREEN10CM14/38 | F5: Number | G5: Canner Connectors | H5: 1
A6: 184 | B6: A | C6: Cable Crimped JST One Side Violet 10cm | D6: CAB-CRI-2515VOILET10CM14/38 | F6: Number | G6: Canner Connectors | H6: 1
A7: 185 | B7: A | C7: Cable Crimped JST One Side Yellow 10cm | D7: CAB-CRI-2515YELLOW10CM14/38 | F7: Number | G7: Canner Connectors | H7: 1
A8: 186 | B8: A | C8: Cable Crimped JST One Side Sky Blue 10cm | D8: CAB-CRI-2515SBLUE10CM14/38 | F8: Number | G8: Canner Connectors | H8: 1
A9: 187 | B9: A | C9: Cable Crimped JST One Side Pink 10cm | D9: CAB-CRI-2515PINK10CM14/38 | F9: Number | G9: Canner Connectors | H9: 1
A10: 188 | B10: A | C10: Cable Crimped JST One Side Orange 10cm | D10: CAB-CRI-2515ORANGE10CM14/38 | F10: Number | G10: Canner Connectors | H10: 1
A11: 190 | B11: A | C11: Cable Crimped JST One Side Light Brown 10cm | D11: CAB-CRI-2515LBROWN10CM14/38 | F11: Number | G11: Canner Connectors | H11: 1
A12: 192 | B12: A | C12: Cable Crimped JST One Side White with Red Strip 10cm | D12: CAB-CRI-2515WHITERED10CM14/38 | F12: Number | G12: Canner Connectors | H12: 1
A13: 193 | B13: A | C13: Cable Crimped JST One Side White with Black Strip 10cm | D13: CAB-CRI-2515WHITEBLACK10CM14/38 | F13: Number | G13: Canner Connectors | H13: 1
... A17: 198 | B17: A | C17: Cable Crimped JST One Side Cyan 10cm | D17: CAB-CRI-2515CYAN10CM14/38 | F17: Number | G17: Canner Connectors | H17: 1
A18: 267 | B18: A | C18: Connector Circular PM Male SY21-15 Pin | D18: CON-CRC-SY21BY-PM-M15PL67 | E18: SY2112/P15-1N | F18: Number | G18: Weipu | H18: 1
A19: 427 | B19: A | C19: HeatShrink Tube 1.5mm/1.6mm | D19: SLN-STB-1.6M-4X-BK | F19: cm | G19: Suzhou Volsun Electronics Technology | H19: 15

Sheet 15-Current Sensor Assy
A1: Sl No. | B1: whether LifeBuoy? | C1: RAW MATERIAL NAME | D1: SAS Part Number | E1: OEM Part Number | F1: UNIT OF MEASURE | G1: SUPPLIER | H1: Current Sensor Assy
A2: 58 | B2: A | C2: PCB of Current Sensor | D2: PCB-CUR-SENSOR | F2: Number | G2: JLC | H2: 1
A3: 68 | B3: A | C3: WCS1700 CT Coil current Sensor | D3: SEN-CUR-WCS1700-CTi35 | F3: Number | G3: Evelta | H3: 2
A4: 86 | B4: A | C4: Capacitor 0.1uF 0805 | D4: CAP-SMD-0805-100V10P-0D1uF | E4: 0805B104K101CT | F4: Number | G4: Seutes | H4: 2
A5: 127 | B5: A | C5: 15K 0805 Commercial quality | D5: RES-SMD-0805-125mW5P-15k | E5: N/A | F5: Number | G5: Roland | H5: 2
A6: 149 | C6: Male Bergstrip Right angle strip 40x1 2.54mm | F6: Strips | G6: Roland | H6: 0.2

Sheet 14-100v Buck PCB Assy
A1: Sl No. | B1: whether LifeBuoy? | C1: RAW MATERIAL NAME | D1: SAS Part Number | E1: OEM Part Number | F1: UNIT OF MEASURE | G1: SUPPLIER | H1: 100v Buck PCB Assy
A2: 4 | B2: A | C2: Schottky Diode SS310 100v1A | D2: SIC-DIO-SS310-v100i1 | E2: Robu-R193145 | F2: Number | G2: Robu | H2: 1
A3: 65 | B3: A | C3: PCB of MP9486 on XL7015 FootPrint | D3: PCB-XL7015FOOT-MP9486 | F3: Number | G3: JLC | H3: 1
A4: 80 | B4: A | C4: Lead Paste | D4: SOL-PAS-6040-ROHS | F4: Grm | G4: Roland | H4: 2
A5: 86 | B5: A | C5: Capacitor 0.1uF 0805 | D5: CAP-SMD-0805-100V10P-0D1uF | E5: 0805B104K101CT | F5: Number | G5: Seutes | H5: 2
A6: 92 | B6: A | C6: MP9486AGN-Z 100v Buck converter IC | D6: SIC-BUK-MP9486AGN-Z-100v1A | E6: MP9486AGN-Z | F6: Number | G6: Seutes | H6: 1
A7: 100 | B7: A | C7: 10k 0805 resistor | D7: RES-SMD-0805-125mW5P-10k | E7: ERA6AEB103V (to be modified) | F7: Number | G7: Seutes | H7: 1
A8: 101 | B8: A | C8: 510K Resistor | D8: RES-SMD-0805-125mW5P-510k | F8: Number | G8: Robu | H8: 1
A9: 112 | B9: A | C9: Capacitor Electrolytic 10uF 63v 2.54mm pitch | F9: Number | G9: Roland | H9: 2
A10: 116 | B10: A | C10: 33uH 3.5A SMD Inductor | D10: IDR-SMD-SPM7054-uH33i3.5 | E10: SPM7054VC-330M-D | F10: Number | G10: Seutes | H10: 1
A11: 123 | B11: A | C11: 30k 0805 Yageo | D11: RES-SMD-0805-125mW5P-30k | E11: RT0805FRE0730KL-YAGEO | F11: Number | G11: Robu | H11: 1

Sheet 13-Motherboard Assy
A1: Sl No. | B1: whether LifeBuoy? | C1: RAW MATERIAL NAME | D1: SAS Part Number | E1: OEM Part Number | F1: UNIT OF MEASURE | G1: SUPPLIER | H1: Motherboard Assy
A2: 2 | B2: A | C2: Receiver Module R9MM (R9MM will come July25)/R9Mini | D2: RAD-TRR-R9MI1W915 | E2: Robu-866205 | F2: Number | G2: Robu | H2: 1
A3: 3 | B3: A | C3: Free Wheel Diode SMD M7 | D3: SIC-DIO-M7-v100i1 | E3: Robu-597541 | F3: Number | G3: Robu | H3: 7
A4: 5 | B4: A | C4: Voltage Regulator AMS1117 5.0v | D4: SIC-REG-AMS1117-5v | E4: Robu-162035 | F4: Number | G4: Robu | H4: 3
A5: 7 | B5: A | C5: GPS Module LC86L | D5: MOD-GNS-LC86L | E5: LC86L | F5: Number | G5: Roland | H5: 1
A6: 12 | B6: A | C6: Bullet Connector Female 4mm AMASS | D6: CON-BUL-4F | E6: Robu-R150111 | F6: Number | G6: Robu | H6: 2
A7: 14 | B7: A | C7: Bullet Connector Female 2mm AMASS | D7: CON-BUL-2F | E7: Robu-R150107 | F7: Number | G7: Robu | H7: 1
A8: 16 | B8: A | C8: Bullet Connector Female 6mm XT-150 AMASS | D8: CON-BUL-6F | E8: Robu-239593 | F8: Number | G8: Robu | H8: 1
A9: 38 | B9: A | C9: Buck Coverter Module LM2596HVS | D9: MOD-BUK-LM2596HVSv48i2 | E9: Robu-766328 | F9: Number | G9: Robu | H9: 1
A10: 57 | B10: A | C10: PCB of A4 Motherboard/A42 Motherboard | D10: PCB-A4MEGA328P-MUR | F10: Number | G10: JLC | H10: 1
A11: 80 | B11: A | C11: Lead Paste | D11: SOL-PAS-6040-ROHS | F11: Grm | G11: Roland | H11: 2
A12: 81 | B12: A | C12: Lead Wire 22AWG | D12: SOL-WIR-6040-ROHS-22AWG | F12: grm | G12: Roland | H12: 5
A13: 82 | B13: A | C13: Voltage Regulator 3.3v SOT-223-4 | D13: SIC-REG-AMS1117-33v | E13: LD1117S33CTR | F13: Number | G13: Seutes | H13: 2
A14: 85 | B14: A | C14: Comparator IC - LM358DT SMD | D14: SIC-COM-LM358DT | E14: LM358DT | F14: Number | G14: Seutes | H14: 1
A15: 86 | B15: A | C15: Capacitor 0.1uF 0805 | D15: CAP-SMD-0805-100V10P-0D1uF | E15: 0805B104K101CT | F15: Number | G15: Seutes | H15: 4
A16: 88 | B16: A | C16: LED 0805 SMD | D16: IND-SMD-2D2v-RED | E16: KPTD-2012LVSURCK | F16: Number | G16: Seutes | H16: 1
A17: 89 | B17: A | C17: SSR-SPDT - TS5A3157DBVR | D17: SIC-SSR-TS5A3157DBVR | E17: TS5A3157DBVR | F17: Number | G17: Seutes | H17: 1
A18: 95 | B18: A | C18: 1N4148 SMD | D18: SIC-DIO-1N4148-100V1A | E18: 1N4148W-7-F | F18: Number | G18: Seutes | H18: 4
A19: 96 | B19: A | C19: 18pF 0805 capacitor | D19: CAP-SMD-0805-50V5P-18pF | E19: MC0805N180J500CT | F19: Number | G19: Seutes | H19: 4
A20: 98 | B20: A | C20: 10uF 10v Tantalum Capacitor Case A | D20: CAP-SMD-TANTA-10V10P-10UF | E20: T491A106K010AT | F20: Number | G20: Seutes | H20: 6
A21: 99 | C21: 1k 0805 Resistor | D21: RES-SMD-0805-125mW5P-1k | E21: ERA6AEB102V (to be modified) | F21: Number | G21: Seutes | H21: 1
A22: 100 | B22: A | C22: 10k 0805 resistor | D22: RES-SMD-0805-125mW5P-10k | E22: ERA6AEB103V (to be modified) | F22: Number | G22: Seutes | H22: 1
A23: 103 | B23: A | C23: 330E 0805 Resistor | D23: RES-SMD-0805-125mW1P-330E | E23: MCWR08X3300FTL (to be modified) | F23: Number | G23: Seutes | H23: 12
A24: 104 | B24: A | C24: 22E 3W 2512 SMD Resistor | D24: RES-SMD-0805-3W1P-22E | E24: 352222RJT/CGS | F24: Number | G24: Seutes | H24: 2
A25: 113 | B25: A | C25: Relay Power SPST 23A-24v | D25: REL-PWR-SPST-24v-V63i23 | E25: G2RL-1A-E2-CV-HA DC24 | F25: Number | G25: Roland | H25: 1
A26: 115 | B26: A | C26: MCP3208 Analog to Digital Conv. | D26: SIC-ADC-MCP3208-5V8CH | E26: MCP3208-CI/SL | F26: Number | G26: Seutes | H26: 2
A27: 118 | B27: A | C27: 47k 0805 PANASONIC | D27: RES-SMD-0805-125mW5P-47k | E27: ERJ6GEYJ473V / MCWR08X4702FTL | F27: Number | G27: Seutes | H27: 8
A28: 121 | B28: A | C28: 20k 0805 PANASONIC | D28: RES-SMD-0805-125mW5P-20k | E28: ERJ-P06F2002V/ | F28: Number | G28: Seutes | H28: 12
A29: 124 | B29: A | C29: 470k 0805 PANASONIC | D29: RES-SMD-0805-500mW5P-470k | E29: ERJUP6F4703V | F29: Number | G29: Seutes | H29: 16
A30: 128 | B30: A | C30: 1uF 0805 PANASONIC | D30: CAP-SMD-0805-25V10P-1uF | E30: GCM21BR71E105KA56L | F30: Number | G30: Seutes | H30: 12
A31: 129 | B31: A | C31: 16MHz Crystal oscillator | D31: OSC-SMD-ABM3-16MHZ-18pF | E31: ABM3-16.000MHZ-B2-T | F31: Number | G31: Seutes | H31: 2
A32: 130 | B32: A | C32: Buffer IC ULN2004 SMA | D32: SIC-AMP-SMD-ULN2004D-50V05A7CH | E32: ULN2004D1013TR | F32: Number | G32: Seutes | H32: 1
A33: 131 | B33: A | C33: SSR AQW282SX | D33: SIC-SSR-AQW282SX-63vD35A-2CH | E33: AQW282SX | F33: Number | G33: Seutes | H33: 6
... A39: 143 | B39: A | C39: BlueTooth Module | D39: MOD-BLE-HC05 | E39: HC-05 | F39: Number | G39: Roland | H39: 1
A40: 148 | B40: A | C40: Male Bergstrip 40x1 2.54mm | D40: CON-BRG-40X1-M2.54MM | F40: Strips | G40: Roland | H40: 0.2
A41: 151 | B41: A | C41: Female Bergstrip 40x1 2.0mm | D41: CON-BRG-40X1-F2MM | F41: Strips | G41: Roland | H41: 0.2
A42: 152 | B42: A | C42: Male Bergstrip 40x1 2.0mm | D42: CON-BRG-40X1-M2MM | F42: Strips | G42: Roland | H42: 0.2
A43: 136 | B43: A | C43: Connector Male 3 pin 2510 | D43: CON-RMC-M3 | F43: Number | G43: Robu | H43: 3
A44: 156 | B44: A | C44: Connector Male 5 pin 2510 | D44: CON-RMC-M5 | F44: Number | G44: Roland | H44: 2
A45: 163 | B45: A | C45: Connector Male 2 pin JST-XH Top Entry | D45: CON-JXH-TOP-M2 | F45: Number | G45: Canner Connectors | H45: 1
...

Sheet 12-ElecBox Assy
A1: Sl No. | B1: whether LifeBuoy? | C1: RAW MATERIAL NAME | D1: SAS Part Number | E1: OEM Part Number | F1: UNIT OF MEASURE | G1: SUPPLIER | H1: ElecBox Assy
A2: 2 | B2: A | C2: Receiver Module R9MM (R9MM will come July25)/R9Mini | D2: RAD-TRR-R9MI1W915 | E2: Robu-866205 | F2: Number | G2: Robu | H2: 1
A3: 12 | B3: A | C3: Bullet Connector Female 4mm AMASS | D3: CON-BUL-4F | E3: Robu-R150111 | F3: Number | G3: Robu | H3: 2
A4: 13 | B4: A | C4: Bullet Connector Male 2mm AMASS | D4: CON-BUL-2M | E4: Robu-R150108 | F4: Number | G4: Robu | H4: 2
A5: 15 | B5: A | C5: Bullet Connector Male 6mm XT-150 AMASS | D5: CON-BUL-6M | E5: Robu-239520 | F5: Number | G5: Robu | H5: 1
A6: 16 | B6: A | C6: Bullet Connector Female 6mm XT-150 AMASS | D6: CON-BUL-6F | E6: Robu-239593 | F6: Number | G6: Robu | H6: 1
A7: 22 | B7: A | C7: Cable - Ultra Flexible - Red 10AWG | D7: CAB-SIL-RED10AWG | F7: Meter | G7: Robu | H7: 0.25
A8: 24 | B8: A | C8: Cable - Ultra Flexible - Red 12AWG | D8: CAB-SIL-RED12AWG | E8: Robu-1824982 | F8: Meter | G8: Robu | H8: 0.5
A9: 153 | B9: A | C9: Conformal Coating | D9: EAC-CONFORMAL | F9: ml | G9: Roland | H9: 10
A10: 203 | B10: A | C10: Cable Extension Converter Ipex4 to SMA (for R9MM ipex4) 15cm | D10: CAB-CAX-SMAFtoIPEX11.13 | E10: Robu: 1675004 | F10: Number | G10: Synergy | H10: 1
A11: 253 | B11: A | C11: Electronic Box Top Lid | D11: FAB-IJM-ElecBox-TopLid | F11: Number | G11: Janki Die | H11: 1
A12: 294 | B12: A | C12: Indicator Panel Mount - BlueRobotics | D12: IND-PAM-Al68-12V | E12: BR-100551-001 | F12: Number | G12: BlueRobotics | H12: 1
A13: 295 | B13: A | C13: Rotary Main Switch - BlueRobotics - IP68 | D13: SWI-ROT-BLUEROBOTICS-v63i5 | E13: BR-100433 | F13: Number | G13: BlueRobotics | H13: 1
A14: 313 | B14: A | C14: Bolt CSK Head M4x8 Phillips GI | D14: FAS-BLT-CSK-4M8M-PH-GI | F14: Number | G14: Dynamic Industrial Supplier | H14: 4
A15: 318 | B15: A | C15: M4x20 CSK Phillips - Electronic Box top lid | D15: FAS-BLT-CSK-4M20M-PH-304SS | F15: Number | G15: Dynamic Industrial Supplier | H15: 4
A16: 401 | B16: A | C16: Cable gland PG-7 | D16: MAC-GLA-PG7-PL | F16: Number | G16: NDP | H16: 3
A17: 409 | B17: A | C17: Electronic Box - Shell | D17: FAB-IJM-EBX | F17: Number | G17: Janki Die | H17: 1
A18: 410 | B18: A | C18: Electronic Box - Front Lid | D18: FAB-IJM-FLID-LIFE | F18: Number | G18: Janki Die | H18: 1
A19: 426 | B19: A | C19: HeatShrink Tube 4.8/1.2 Adhesive Lined Black | D19: SLN-STB-4.8M-4X-BK-ADH | F19: cm | G19: Suzhou Volsun Electronics Technology | H19: 10
A20: 655 | B20: A | C20: Silica Gel Packet 10gms | F20: Number | G20: Local Market | H20: 1
A21: 656 | B21: A | C21: QC Sticker | F21: Number | G21: Local Market | H21: 1
A22: 698 | B22: A | C22: Motherboard Assy | E22: 13 | F22: Number | G22: In House | H22: 1
A23: 701 | B23: A | C23: Signal PM Assy | E23: 16 | F23: Number | G23: In House | H23: 2
A24: 702 | B24: A | C24: Charging PM Assy | D24: ASYE-MCH-IP7-FLSHM-ST | E24: 17 | F24: Number | G24: In House | H24: 1

Sheet 11-IP Remote Assy
A1: Sl No. | B1: whether LifeBuoy? | C1: RAW MATERIAL NAME | D1: SAS Part Number | E1: OEM Part Number | F1: UNIT OF MEASURE | G1: SUPPLIER | H1: IP Remote Assy
A2: 1 | B2: A | C2: Transmitter with Receiver Module 2.4G0.9k | D2: RAD-TRR-QX71W915 | E2: Robu-866205 | F2: Number | G2: Robu | H2: 1
A3: 59 | B3: A | C3: PWB of Button -2 | D3: PCB-QX7-BUTTON | F3: Number | G3: JLC | H3: 2
A4: 70 | B4: A | C4: Lithium Ion Battery Block 6X3 with Samsung 50S 21700 | D4: PWR-BLK-6x3-50S | E4: 50S | F4: Number | G4: Ampower India | H4: 2
A5: 73 | B5: A | C5: Lithium Ion Cell Samsung 21700 50S | D5: PWR-BAR-2170-50S | F5: Number | G5: Ampower India | H5: 2
A6: 81 | B6: A | C6: Lead Wire 22AWG | D6: SOL-WIR-6040-ROHS-22AWG | F6: grm | G6: Roland | H6: 5
A7: 141 | B7: A | C7: SD Card 32GB | D7: MOD-SDCARD-32GB-CLASS10A | F7: Number | G7: Roland | H7: 1
A8: 160 | B8: A | C8: 3 pin JST-XH housing | D8: CON-JXH-HOS-F3 | F8: Number | G8: Canner Connectors | H8: 1
A9: 179 | B9: A | C9: Cable Crimped JST-XH One Side Red 25cm 14/38 Wire | D9: CAB-CRI-2511RED25CM14/38 | F9: Number | G9: Canner Connectors | H9: 1
A10: 180 | B10: A | C10: Cable Crimped JST-XH One Side Green 25cm 14/38 wire | D10: CAB-CRI-2511GREEN25CM14/38 | F10: Number | G10: Canner Connectors | H10: 1
A11: 181 | B11: A | C11: Cable Crimped JST-XH One Side Black 25cm 14/38 wire | D11: CAB-CRI-2511BLACK25CM14/38 | F11: Number | G11: Canner Connectors | H11: 1
A12: 204 | B12: A | C12: Cable Extension R9M Antenna - RP-SMA to Open 20cm | D12: CAB-CAX-RPSMAFtoOPEN1.13 | F12: Number | G12: Synergy | H12: 1
A13: 218 | B13: A | C13: 12 Core Wire 14/38 | D13: CAB-MCO-12C14/38LENChetan | F13: Meter | G13: Cable Fort | H13: 0.2
A14: 275 | B14: A | C14: Connector Circular Push Pull CM Male SA12 9pin | D14: CON-CRC-SA12PF-CM-M9AL67-ST | E14: SA1210/P9IB | F14: Number | G14: Weipu | H14: 1
A15: 276 | B15: A | C15: Connector Circular Push Pull PM Female SA12 9pin | D15: CON-CRC-SA12PF-PM-F9AL67-ST | E15: SA1212/S9B | F15: Number | G15: Weipu | H15: 1
A16: 298 | B16: A | C16: Bolt Self Tap Screw No. 4 M4x6.5 Philips SS304 - Remote | D16: FAS-TAP-4No605MPH304SS | F16: Number | G16: Dynamic Industrial Supplier | H16: 12
A17: 299 | B17: A | C17: M2x9.5 Selp tapping SS304 - Remote | D17: FAS-TAP-2No605MPH304SS | F17: Number | G17: Dynamic Industrial Supplier | H17: 6
A18: 316 | B18: A | C18: M2x12 Allen Cap | D18: FAS-BLT-ALN-2M12M-HX-304SS | F18: Number | G18: Dynamic Industrial Supplier | H18: 20
A19: 413 | B19: A | C19: Remote - Upper Shell Water Proof | D19: FAB-IJM-QX7-UPPERSHELL | F19: Number | G19: Webel | H19: 1
A20: 414 | B20: A | C20: Remote - Lower Shell Water Proof | D20: FAB-IJM-QX7-LOWERSHELL | F20: Number | G20: Webel | H20: 1
A21: 438 | B21: A | C21: Sealant Teroson MS930 | D21: SLN-SMP-MS930-400ML | F21: ml | G21: Innovine Tech Marketing PVt. Ltd. | H21: 10
A22: 441 | B22: A | C22: Industrial RTV Silicon Sealant for Gasketting | F22: ml | G22: Royal Tools & Hardware | H22: 7
A23: 508 | B23: A | C23: Hot Glue stick 11mm | D23: nu` | F23: Number | G23: Local Market | H23: 0.1
A24: 516 | B24: A | C24: Button spacer No. 1/1 3D Print | F24: Number | G24: In-house | H24: 1
A25: 517 | B25: A | C25: Button Spacer No. 1/2 3D Print | F25: Number | G25: In-house | H25: 1
A26: 518 | B26: A | C26: Button Spacer No. 2 3D Print | F26: Number | G26: In-house | H26: 2
A27: 519 | B27: A | C27: Remote - Button No. 1 Pressure Bracket 3D Print | D27: FAB-3DP-QX7-PRES-BRAC | F27: Number | G27: In-house | H27: 2
A28: 520 | B28: A | C28: Remote - Battery Holding Bracket 3D Print | D28: FAB-3DP-QX7-BAT-BRAC | F28: Number | G28: In-house | H28: 4
A29: 522 | B29: A | C29: Remote - Straps Lanyard | D29: FAB-STC-QX7-STRAP | F29: Number | G29: Local Market Kolkata | H29: 1
A30: 526 | B30: A | C30: Remote - Antenna clamp -1 3D Print | D30: FAB-3DP-QX7-ANT-CLMP1 | F30: Number | G30: In-house | H30: 1
A31: 527 | B31: A | C31: Remote - Antenna Clamp -2 3D Print | D31: FAB-3DP-QX7-ANT-CLMP2 | F31: Number | G31: In-house | H31: 1
A32: 528 | B32: A | C32: Remote - LCD Holder Bracket 3D Print | D32: FAB-3DP-QX7-LCD-HOLD | F32: Number | G32: In House | H32: 1
A33: 544 | B33: A | C33: Remote - Polycarbonate Glass for LCD Screen on Remote | D33: FAB-QX7-IPREMOTE-GLASS | F33: Number | G33: Local Market | H33: 1
A34: 553 | C34: Foam Gasket 40mm width 5mm thick | F34: cm | H34: 2
A35: 558 | B35: A | C35: Remote - Silicon Water Proof Rubber Boot For Joystick | D35: SLN-BOOT-JOYSTICK | F35: Number | G35: Ali Irani - Kolkata | H35: 2
A36: 559 | B36: A | C36: Remote - Silicon Water Proof Button Cover No. 1 | D36: SLN-BOOT-BUTTON1 | F36: Number | G36: Ali Irani - Kolkata | H36: 2
A37: 560 | B37: A | C37: Remote - Silicon Water Proof Button Cover No. 2 | D37: SLN-BOOT-BUTTON2 | F37: Number | G37: Ali Irani - Kolkata | H37: 2
A38: 561 | C38: Foam Gasket 25mm width 3mm thick | H38: 2
A39: 716 | B39: A | C39: IP Remote Charging PM | E39: 31 | F39: Number | G39: In House | H39: 1

Sheet 10-Battery Wiring PORT Assy 
A1: Sl No. | B1: whether LifeBuoy? | C1: RAW MATERIAL NAME | D1: SAS Part Number | E1: OEM Part Number | F1: UNIT OF MEASURE | G1: SUPPLIER | H1: Battery Wiring PORT Assy
A2: 15 | B2: A | C2: Bullet Connector Male 6mm XT-150 AMASS | D2: CON-BUL-6M | E2: Robu-239520 | F2: Number | G2: Robu | H2: 1
A3: 16 | B3: A | C3: Bullet Connector Female 6mm XT-150 AMASS | D3: CON-BUL-6F | E3: Robu-239593 | F3: Number | G3: Robu | H3: 1
A4: 21 | B4: A | C4: Cable - Ultra Flexible - Black 10AWG | D4: CAB-SIL-BLACK10AWG | F4: Meter | G4: Robu | H4: 0.23
A5: 22 | B5: A | C5: Cable - Ultra Flexible - Red 10AWG | D5: CAB-SIL-RED10AWG | F5: Meter | G5: Robu | H5: 0.35
A6: 117 | B6: A | C6: LM61 Temperature Sensor | D6: SEN-TEM-LM61 | E6: LM61BIZ/NOPB | F6: Number | G6: Seutes | H6: 1
A7: 218 | B7: A | C7: 12 Core Wire 14/38 | D7: CAB-MCO-12C14/38LENChetan | F7: Meter | G7: Cable Fort | H7: 0.3
A8: 277 | B8: A | C8: Connector Circular Push Pull CM Female SA12 9pin | D8: CON-CRC-SA12PF-CM-F9AL67-ST | E8: SA1211/S9IB | F8: Number | G8: Weipu | H8: 1
A9: 398 | B9: A | C9: Soldering Lead Wire 6040 16AWG | D9: SOL-WIR-6040-ROHS-16AWG | F9: Grm | G9: ARB Accessories | H9: 20
A10: 420 | B10: A | C10: Heatshrink Tube 6.4:1.6 Adhesive Lined Black | D10: SLN-STB-6.4M-4X-BK-ADH | F10: cm | G10: Suzhou Volsun Electronics Technology | H10: 3.5
A11: 421 | B11: A | C11: Heatshrink Tube 9.5mm Adhesive Lined Black | D11: SLN-STB-9.5M-3X-BK-ADH | F11: cm | G11: Suzhou Volsun Electronics Technology | H11: 3.5
A12: 427 | B12: A | C12: HeatShrink Tube 1.5mm/1.6mm | D12: SLN-STB-1.6M-4X-BK | F12: cm | G12: Suzhou Volsun Electronics Technology | H12: 9

Sheet 9-Battery wiring STBD Assy
A1: Sl No. | B1: whether LifeBuoy? | C1: RAW MATERIAL NAME | D1: SAS Part Number | E1: OEM Part Number | F1: UNIT OF MEASURE | G1: SUPPLIER | H1: Battery wiring STBD Assy
A2: 15 | B2: A | C2: Bullet Connector Male 6mm XT-150 AMASS | D2: CON-BUL-6M | E2: Robu-239520 | F2: Number | G2: Robu | H2: 1
A3: 16 | B3: A | C3: Bullet Connector Female 6mm XT-150 AMASS | D3: CON-BUL-6F | E3: Robu-239593 | F3: Number | G3: Robu | H3: 1
A4: 21 | B4: A | C4: Cable - Ultra Flexible - Black 10AWG | D4: CAB-SIL-BLACK10AWG | F4: Meter | G4: Robu | H4: 0.23
A5: 22 | B5: A | C5: Cable - Ultra Flexible - Red 10AWG | D5: CAB-SIL-RED10AWG | F5: Meter | G5: Robu | H5: 0.35
A6: 117 | B6: A | C6: LM61 Temperature Sensor | D6: SEN-TEM-LM61 | E6: LM61BIZ/NOPB | F6: Number | G6: Seutes | H6: 1
A7: 218 | B7: A | C7: 12 Core Wire 14/38 | D7: CAB-MCO-12C14/38LENChetan | F7: Meter | G7: Cable Fort | H7: 0.3
A8: 277 | B8: A | C8: Connector Circular Push Pull CM Female SA12 9pin | D8: CON-CRC-SA12PF-CM-F9AL67-ST | E8: SA1211/S9IB | F8: Number | G8: Weipu | H8: 1
A9: 398 | B9: A | C9: Soldering Lead Wire 6040 16AWG | D9: SOL-WIR-6040-ROHS-16AWG | F9: Grm | G9: ARB Accessories | H9: 20
A10: 420 | B10: A | C10: Heatshrink Tube 6.4:1.6 Adhesive Lined Black | D10: SLN-STB-6.4M-4X-BK-ADH | F10: cm | G10: Suzhou Volsun Electronics Technology | H10: 3.5
A11: 421 | B11: A | C11: Heatshrink Tube 9.5mm Adhesive Lined Black | D11: SLN-STB-9.5M-3X-BK-ADH | F11: cm | G11: Suzhou Volsun Electronics Technology | H11: 3.5
A12: 427 | B12: A | C12: HeatShrink Tube 1.5mm/1.6mm | D12: SLN-STB-1.6M-4X-BK | F12: cm | G12: Suzhou Volsun Electronics Technology | H12: 9

Sheet 8-Battery Block Formation Assy
A1: Sl No. | B1: whether LifeBuoy? | C1: RAW MATERIAL NAME | D1: SAS Part Number | E1: OEM Part Number | F1: UNIT OF MEASURE | G1: SUPPLIER | H1: Battery Block Formation Assy
B2: A | H2: 8
A3: 69 | B3: A | C3: 21700 Cell Holder 1x3 21.2mm bore | D3: PWR-CELL-HOLDER-1x3-21700-21.2MM | F3: Number | G3: Quartz Components | H3: 12
A4: 73 | B4: A | C4: Lithium Ion Cell Samsung 21700 50S | D4: PWR-BAR-2170-50S | F4: Number | G4: Ampower India | H4: 18
A5: 393 | B5: A | C5: 65mm Paper Separator | F5: cm | G5: ARB Accessories | H5: 35
A6: 394 | B6: A | C6: Barley ring for 21700 cylindrical cell | F6: Number | G6: ARB Accessories | H6: 18
A7: 398 | B7: A | C7: Soldering Lead Wire 6040 16AWG | D7: SOL-WIR-6040-ROHS-16AWG | F7: Grm | G7: ARB Accessories | H7: 10
A8: 691 | B8: A | C8: Copper Tab Tinning Assy | D8: ASSY-MCN-3S2P-CU-2170 | E8: 7 | F8: Number | G8: In House | H8: 5

Sheet 7-Copper Tab Tinning Assy
A1: Sl No. | B1: whether LifeBuoy? | C1: RAW MATERIAL NAME | D1: SAS Part Number | E1: OEM Part Number | F1: UNIT OF MEASURE | G1: SUPPLIER | H1: Copper Tab Tinning Assy
A2: 391 | B2: A | C2: Copper Strips 3x2 Cells | D2: FAB-MCN-3S2P-CU-2170 | F2: Number | G2: Naveen | H2: 5
A3: 398 | B3: A | C3: Soldering Lead Wire 6040 16AWG | D3: SOL-WIR-6040-ROHS-16AWG | F3: Grm | G3: ARB Accessories | H3: 20

Sheet 6-Signal Cable Assy 
A1: Sl No. | B1: whether LifeBuoy? | C1: RAW MATERIAL NAME | D1: SAS Part Number | E1: OEM Part Number | F1: UNIT OF MEASURE | G1: SUPPLIER | H1: Signal Cable Assy
A2: 14 | B2: A | C2: Bullet Connector Female 2mm AMASS | D2: CON-BUL-2F | E2: Robu-R150107 | F2: Number | G2: Robu | H2: 1
A3: 81 | B3: A | C3: Lead Wire 22AWG | D3: SOL-WIR-6040-ROHS-22AWG | F3: grm | G3: Roland | H3: 5
A4: 218 | B4: A | C4: 12 Core Wire 14/38 | D4: CAB-MCO-12C14/38LENChetan | F4: Meter | G4: Cable Fort | H4: 0.8
A5: 268 | B5: A | C5: Connector Circular CM Female SY21-15 Pin | D5: CON-CRC-SY21BY-CM-F15PL67 | E5: SY2116/S15II-1N | F5: Number | G5: Weipu | H5: 1
A6: 275 | B6: A | C6: Connector Circular Push Pull CM Male SA12 9pin | D6: CON-CRC-SA12PF-CM-M9AL67-ST | E6: SA1210/P9IB | F6: Number | G6: Weipu | H6: 1
A7: 293 | B7: A | C7: Leak Probe Sponge - BlueRobotics | D7: SEN-LEK-BLUEROBOTICS-PROB | E7: BR-100954 | F7: Number | G7: BlueRobotics | H7: 1
A8: 423 | B8: A | C8: HeatShrink Tube 3.2 mm Adhesive Lined Black | D8: SLN-STB-3M-3X-BK-ADH | F8: cm | G8: Suzhou Volsun Electronics Technology | H8: 6
A9: 427 | B9: A | C9: HeatShrink Tube 1.5mm/1.6mm | D9: SLN-STB-1.6M-4X-BK | F9: cm | G9: Suzhou Volsun Electronics Technology | H9: 25
A10: 690 | B10: A | C10: Jet unit Signal Cable Orig. Assy (CMO) | E10: 5 | F10: Number | G10: In House | H10: 1

Sheet 5-Jet unit Signal Cable Orig. A
A1: Sl No. | B1: whether LifeBuoy? | C1: RAW MATERIAL NAME | D1: SAS Part Number | E1: OEM Part Number | F1: UNIT OF MEASURE | G1: SUPPLIER | H1: Jet unit Signal Cable Orig. Assy (CMO)
A2: 81 | B2: A | C2: Lead Wire 22AWG | D2: SOL-WIR-6040-ROHS-22AWG | F2: grm | G2: Roland | H2: 2
A3: 221 | B3: A | C3: 6 Core Wire 14/38 | D3: CAB-MCO-6C14/38LENChetan | F3: Meter | G3: Cable Fort | H3: 0.2
A4: 289 | B4: A | C4: LP12 6 pin socket female clip lock CM | D4: CON-CRS-LP12PF-CM-F6PL67-ST | E4: LP-12-J06PP-03-001 | F4: Number | G4: Evelta | H4: 1
A5: 427 | B5: A | C5: HeatShrink Tube 1.5mm/1.6mm | D5: SLN-STB-1.6M-4X-BK | F5: cm | G5: Suzhou Volsun Electronics Technology | H5: 6

Sheet 4-Jet unit Signl Cbl Dest. Assy
A1: Sl No. | B1: whether LifeBuoy? | C1: RAW MATERIAL NAME | D1: SAS Part Number | E1: OEM Part Number | F1: UNIT OF MEASURE | G1: SUPPLIER | H1: Jet unit Signal Cable Dest. Assy (CMD)
A2: 81 | B2: A | C2: Lead Wire 22AWG | D2: SOL-WIR-6040-ROHS-22AWG | F2: grm | G2: Roland | H2: 2
A3: 221 | B3: A | C3: 6 Core Wire 14/38 | D3: CAB-MCO-6C14/38LENChetan | F3: Meter | G3: Cable Fort | H3: 0.65
A4: 288 | B4: A | C4: LP12 6 pin plug male clip lock CM | D4: CON-CRS-LP12PF-CM-M6PL67-ST | E4: LP-12-C06PE-02-001 | F4: Number | G4: Evelta | H4: 1
A5: 293 | B5: A | C5: Leak Probe Sponge - BlueRobotics | D5: SEN-LEK-BLUEROBOTICS-PROB | E5: BR-100954 | F5: Number | G5: BlueRobotics | H5: 1
A6: 427 | B6: A | C6: HeatShrink Tube 1.5mm/1.6mm | D6: SLN-STB-1.6M-4X-BK | F6: cm | G6: Suzhou Volsun Electronics Technology | H6: 6

Sheet Purchase Order List
A1: PO. No. | B1: Dated | C1: Vendor Name | D1: Brief Item Description | E1: Value
A2: PO#: SAS-PO-25-MARK180-1001 | B2: 18.07.25 | C2: SINO INDIA TRADING COMPANY | D2: ESC | E2: 8600
A3: PO#: SAS-PO-25-MARK180-1002 | B3: 21.07.2025 | C3: DB Smelting | D3: Water Jets | E3: ₹ 3037178.40
A4: PO#: SAS-PO-25-MARK180-1003 | B4: 21.07.2025 | C4: Seutes Technologies | D4: Discrete Electoronic Components | E4: INR 478000.00+ 778
A5: PO#: SAS-PO-25-MARK180-1004 | B5: 21.07.2025 | C5: Macfos Ltd. | D5: Discrete Electoronic Components | E5: INR 132882.16
A6: PO#: SAS-PO-25-MARK180-1005 | B6: 21.07.2025 | C6: Macfos Ltd. | D6: Remote & Receiver
A7: PO#: SAS-PO-25-MARK180-1006 | B7: 21.07.2025 | C7: Premier Electronics | D7: LEDs | E7: INR 18408.00
A8: PO#: SAS-PO-25-MARK180-1007 | B8: 30.07.2025 | C8: Janki Die | D8: Bottom Inlet block, Flashing light | E8: INR 46,232.4
A9: PO#: SAS-PO-25-MARK180-1008 | B9: 12.08.2025 | C9: SVTherm | D9: heat Pipes | E9: INR 20,67,260
A10: PO#: SAS-PO-25-MARK180-1009 | B10: 23.08.2025 | C10: Vinod rai | D10: hull, sr structure, sr pillow | E10: INR 21,19,221.00
A11: PO#: SAS-PO-25-MARK180-1010 | B11: 23.08.2025 | C11: Ambica | D11: AFT plate in Aluminium | E11: INR 1,71,050.00
A12: PO#: SAS-PO-25-MARK180-1011 | B12: 29.08.2025 | C12: Sanjay Techno Plast | D12: Mould Restoration | E12: INR 69,974.00
A13: PO#: SAS-PO-25-MARK180-1012 | B13: 02.09.2025 | C13: Sanjay Techno Plast | D13: Kangaroo Box | E13: INR 1,13,672.94
A14: PO#: SAS-PO-25-MARK180-1013 | B14: 04.09.2025 | C14: Dynamic | D14: Fasteners
A15: PO#: SAS-PO-25-MARK180-1014 | B15: 09.09.2025 | C15: Ambica | D15: Coupling D slot | E15: INR 84,960.00
A16: PO#: SAS-PO-25-MARK180-1015 | B16: 10.09.2025 | C16: Ambica | D16: Jet plate & Heat Side Plate | E16: INR 2,83,200.00

Sheet S-BOM
A1: 9 | B1: SUB-ASSEMBLY BILL OF MATERIAL SHEET
A2: SL NO | B2: SUB ASSEMBLY NAME | C2: RAW MATERIAL NAME | D2: UNITS | E2: UoM | F2: RM USED | G2: RM AVAILABLE | H2: HOW MANY
A3: =IF(B3="","",ROW()-2) -> 1 | B3: Jet Motor Assy | C3: Coupling Hood | D3: 1 | E3: =IF(B3="","",VLOOKUP(C3,RM!$C$4:$F1003,3,FALSE)) -> 0 | F3: =IF(B3="","",IFERROR(SUMIFS(Issue!$D$3:$D1013,Issue!$C$3:$C1013,'S-BOM'!$B3)*'S-BOM'!$D3,"")) -> 0 | G3: {=IFERROR(INDEX(#REF!,MATCH('S-BOM'!$C3,RM!$C$4:$C1003,0)),"")} | H3: =IFERROR(IF(ROUNDDOWN(G3/D3,0)<=0,0,ROUNDDOWN(G3/D3,0)),"")
A4: =IF(B4="","",ROW()-2) -> 2 | B4: Jet Motor Assy | C4: Battery Clamp | D4: 2 | E4: =IF(B4="","",VLOOKUP(C4,RM!$C$4:$F1003,3,FALSE)) -> #N/A | F4: =IF(B4="","",IFERROR(SUMIFS(Issue!$D$3:$D1013,Issue!$C$3:$C1013,'S-BOM'!$B4)*'S-BOM'!$D4,"")) -> 0 | G4: {=IFERROR(INDEX(#REF!,MATCH('S-BOM'!$C4,RM!$C$4:$C1003,0)),"")} | H4: =IFERROR(IF(ROUNDDOWN(G4/D4,0)<=0,0,ROUNDDOWN(G4/D4,0)),"")
A5: =IF(B5="","",ROW()-2) -> 3 | B5: Jet Motor Assy | C5: M4x25 Hex Head | D5: 4 | E5: =IF(B5="","",VLOOKUP(C5,RM!$C$4:$F1003,3,FALSE)) -> #N/A | F5: =IF(B5="","",IFERROR(SUMIFS(Issue!$D$3:$D1013,Issue!$C$3:$C1013,'S-BOM'!$B5)*'S-BOM'!$D5,"")) -> 0 | G5: {=IFERROR(INDEX(#REF!,MATCH('S-BOM'!$C5,RM!$C$4:$C1003,0)),"")} | H5: =IFERROR(IF(ROUNDDOWN(G5/D5,0)<=0,0,ROUNDDOWN(G5/D5,0)),"")
A6: =IF(B6="","",ROW()-2) -> 4 | B6: Jet Motor Assy | C6: M4 Square Nut | D6: 7 | E6: =IF(B6="","",VLOOKUP(C6,RM!$C$4:$F1003,3,FALSE)) -> #N/A | F6: =IF(B6="","",IFERROR(SUMIFS(Issue!$D$3:$D1013,Issue!$C$3:$C1013,'S-BOM'!$B6)*'S-BOM'!$D6,"")) -> 0 | G6: {=IFERROR(INDEX(#REF!,MATCH('S-BOM'!$C6,RM!$C$4:$C1003,0)),"")} | H6: =IFERROR(IF(ROUNDDOWN(G6/D6,0)<=0,0,ROUNDDOWN(G6/D6,0)),"")
A7: =IF(B7="","",ROW()-2) -> 5 | B7: Jet Motor Assy | C7: M4 Nyloc | D7: 16 | E7: =IF(B7="","",VLOOKUP(C7,RM!$C$4:$F1003,3,FALSE)) -> #N/A | F7: =IF(B7="","",IFERROR(SUMIFS(Issue!$D$3:$D1013,Issue!$C$3:$C1013,'S-BOM'!$B7)*'S-BOM'!$D7,"")) -> 0 | G7: {=IFERROR(INDEX(#REF!,MATCH('S-BOM'!$C7,RM!$C$4:$C1003,0)),"")} | H7: =IFERROR(IF(ROUNDDOWN(G7/D7,0)<=0,0,ROUNDDOWN(G7/D7,0)),"")
A8: =IF(B8="","",ROW()-2) -> 6 | B8: Jet Motor Assy | C8: M4 Spring washer | D8: 20 | E8: =IF(B8="","",VLOOKUP(C8,RM!$C$4:$F1003,3,FALSE)) -> #N/A | F8: =IF(B8="","",IFERROR(SUMIFS(Issue!$D$3:$D1013,Issue!$C$3:$C1013,'S-BOM'!$B8)*'S-BOM'!$D8,"")) -> 0 | G8: {=IFERROR(INDEX(#REF!,MATCH('S-BOM'!$C8,RM!$C$4:$C1003,0)),"")} | H8: =IFERROR(IF(ROUNDDOWN(G8/D8,0)<=0,0,ROUNDDOWN(G8/D8,0)),"")
A9: =IF(B9="","",ROW()-2) -> 7 | B9: Jet Motor Assy | C9: M4x12 plain washer | D9: 24 | E9: =IF(B8="","",VLOOKUP(C9,RM!$C$4:$F1003,3,FALSE)) -> #N/A | F9: =IF(B8="","",IFERROR(SUMIFS(Issue!$D$3:$D1013,Issue!$C$3:$C1013,'S-BOM'!$B8)*'S-BOM'!$D9,"")) -> 0 | G9: {=IFERROR(INDEX(#REF!,MATCH('S-BOM'!$C9,RM!$C$4:$C1003,0)),"")} | H9: =IFERROR(IF(ROUNDDOWN(G9/D9,0)<=0,0,ROUNDDOWN(G9/D9,0)),"")
A10: =IF(B10="","",ROW()-2) -> 8 | B10: Jet Motor Assy | C10: M4x16 CSK Phillips | D10: 4 | E10: =IF(B10="","",VLOOKUP(C10,RM!$C$4:$F1003,3,FALSE)) -> #N/A | F10: =IF(B10="","",IFERROR(SUMIFS(Issue!$D$3:$D1013,Issue!$C$3:$C1013,'S-BOM'!$B10)*'S-BOM'!$D10,"")) -> 0 | G10: {=IFERROR(INDEX(#REF!,MATCH('S-BOM'!$C10,RM!$C$4:$C1003,0)),"")} | H10: =IFERROR(IF(ROUNDDOWN(G10/D10,0)<=0,0,ROUNDDOWN(G10/D10,0)),"")
A11: =IF(B11="","",ROW()-2) -> 9 | B11: Jet Motor Assy | C11: M4x10 CSK Phillips | D11: 0 | E11: =IF(B11="","",VLOOKUP(C11,RM!$C$4:$F1003,3,FALSE)) -> #N/A | F11: =IF(B11="","",IFERROR(SUMIFS(Issue!$D$3:$D1013,Issue!$C$3:$C1013,'S-BOM'!$B11)*'S-BOM'!$D11,"")) -> 0 | G11: {=IFERROR(INDEX(#REF!,MATCH('S-BOM'!$C11,RM!$C$4:$C1003,0)),"")} | H11: =IFERROR(IF(ROUNDDOWN(G11/D11,0)<=0,0,ROUNDDOWN(G11/D11,0)),"")
A12: =IF(B12="","",ROW()-2) -> 10 | B12: Jet Motor Assy | C12: M4x20 CSK Phillips | D12: 8 | E12: =IF(B12="","",VLOOKUP(C12,RM!$C$4:$F1003,3,FALSE)) -> #N/A | F12: =IF(B12="","",IFERROR(SUMIFS(Issue!$D$3:$D1013,Issue!$C$3:$C1013,'S-BOM'!$B12)*'S-BOM'!$D12,"")) -> 0 | G12: {=IFERROR(INDEX(#REF!,MATCH('S-BOM'!$C12,RM!$C$4:$C1003,0)),"")} | H12: =IFERROR(IF(ROUNDDOWN(G12/D12,0)<=0,0,ROUNDDOWN(G12/D12,0)),"")
A13: =IF(B13="","",ROW()-2) -> 11 | B13: Jet Motor Assy | C13: Grub M6x10 SS (Coupling tightening) | D13: 2 | E13: =IF(B13="","",VLOOKUP(C13,RM!$C$4:$F1003,3,FALSE)) -> #N/A | F13: =IF(B13="","",IFERROR(SUMIFS(Issue!$D$3:$D1013,Issue!$C$3:$C1013,'S-BOM'!$B13)*'S-BOM'!$D13,"")) -> 0 | G13: {=IFERROR(INDEX(#REF!,MATCH('S-BOM'!$C13,RM!$C$4:$C1003,0)),"")} | H13: =IFERROR(IF(ROUNDDOWN(G13/D13,0)<=0,0,ROUNDDOWN(G13/D13,0)),"")
A14: =IF(B14="","",ROW()-2) -> 12 | B14: Jet Motor Assy | C14: Rotex14 Coupling | D14: 1 | E14: =IF(B14="","",VLOOKUP(C14,RM!$C$4:$F1003,3,FALSE)) -> #N/A | F14: =IF(B14="","",IFERROR(SUMIFS(Issue!$D$3:$D1013,Issue!$C$3:$C1013,'S-BOM'!$B14)*'S-BOM'!$D14,"")) -> 0 | G14: {=IFERROR(INDEX(#REF!,MATCH('S-BOM'!$C14,RM!$C$4:$C1003,0)),"")} | H14: =IFERROR(IF(ROUNDDOWN(G14/D14,0)<=0,0,ROUNDDOWN(G14/D14,0)),"")
A15: =IF(B15="","",ROW()-2) -> 13 | B15: Jet Motor Assy | C15: Teroson MS930 | D15: 15 | E15: =IF(B15="","",VLOOKUP(C15,RM!$C$4:$F1003,3,FALSE)) -> #N/A | F15: =IF(B15="","",IFERROR(SUMIFS(Issue!$D$3:$D1013,Issue!$C$3:$C1013,'S-BOM'!$B15)*'S-BOM'!$D15,"")) -> 0 | G15: {=IFERROR(INDEX(#REF!,MATCH('S-BOM'!$C15,RM!$C$4:$C1003,0)),"")} | H15: =IFERROR(IF(ROUNDDOWN(G15/D15,0)<=0,0,ROUNDDOWN(G15/D15,0)),"")
A16: =IF(B16="","",ROW()-2) -> 14 | B16: Jet Motor Assy | C16: Nozzle on Jet | D16: 1 | E16: =IF(B16="","",VLOOKUP(C16,RM!$C$4:$F1003,3,FALSE)) -> 0 | F16: =IF(B16="","",IFERROR(SUMIFS(Issue!$D$3:$D1013,Issue!$C$3:$C1013,'S-BOM'!$B16)*'S-BOM'!$D16,"")) -> 0 | G16: {=IFERROR(INDEX(#REF!,MATCH('S-BOM'!$C16,RM!$C$4:$C1003,0)),"")} | H16: =IFERROR(IF(ROUNDDOWN(G16/D16,0)<=0,0,ROUNDDOWN(G16/D16,0)),"")
A17: =IF(B17="","",ROW()-2) -> 15 | B17: Jet Motor Assy | C17: Silicon hose pipe clip 7mm | D17: 1 | E17: =IF(B17="","",VLOOKUP(C17,RM!$C$4:$F1003,3,FALSE)) -> #N/A | F17: =IF(B17="","",IFERROR(SUMIFS(Issue!$D$3:$D1013,Issue!$C$3:$C1013,'S-BOM'!$B17)*'S-BOM'!$D17,"")) -> 0 | G17: {=IFERROR(INDEX(#REF!,MATCH('S-BOM'!$C17,RM!$C$4:$C1003,0)),"")} | H17: =IFERROR(IF(ROUNDDOWN(G17/D17,0)<=0,0,ROUNDDOWN(G17/D17,0)),"")
A18: =IF(B18="","",ROW()-2) -> 16 | B18: Jet Motor Assy | C18: Water Jet pump Jet S52 | D18: 1 | E18: =IF(B18="","",VLOOKUP(C18,RM!$C$4:$F1003,3,FALSE)) -> #N/A | F18: =IF(B18="","",IFERROR(SUMIFS(Issue!$D$3:$D1013,Issue!$C$3:$C1013,'S-BOM'!$B18)*'S-BOM'!$D18,"")) -> 0 | G18: {=IFERROR(INDEX(#REF!,MATCH('S-BOM'!$C18,RM!$C$4:$C1003,0)),"")} | H18: =IFERROR(IF(ROUNDDOWN(G18/D18,0)<=0,0,ROUNDDOWN(G18/D18,0)),"")
